Exception in thread Thread-5:
Traceback (most recent call last):
  File "C:\Users\Formateur\AppData\Local\Programs\Python\Python39\lib\threading.py", line 954, in _bootstrap_inner
    self.run()
  File "C:\Users\Formateur\AppData\Local\Programs\Python\Python39\lib\threading.py", line 1266, in run
    self.function(*self.args, **self.kwargs)
  File "C:\pybot\pybot2.py", line 111, in speak_14h
    engine.runAndWait()
  File "C:\Users\Formateur\AppData\Local\Programs\Python\Python39\lib\site-packages\pyttsx3\engine.py", line 177, in runAndWait
    raise RuntimeError('run loop already started')
RuntimeError: run loop already started
Exception in thread Thread-6:
Traceback (most recent call last):
  File "C:\Users\Formateur\AppData\Local\Programs\Python\Python39\lib\threading.py", line 954, in _bootstrap_inner
    self.run()
  File "C:\Users\Formateur\AppData\Local\Programs\Python\Python39\lib\threading.py", line 1266, in run
    self.function(*self.args, **self.kwargs)
  File "C:\pybot\pybot2.py", line 126, in speak_15h
    engine.runAndWait()
  File "C:\Users\Formateur\AppData\Local\Programs\Python\Python39\lib\site-packages\pyttsx3\engine.py", line 177, in runAndWait
    raise RuntimeError('run loop already started')
RuntimeError: run loop already started
Exception in thread Thread-7:
Traceback (most recent call last):
  File "C:\Users\Formateur\AppData\Local\Programs\Python\Python39\lib\threading.py", line 954, in _bootstrap_inner
    self.run()
  File "C:\Users\Formateur\AppData\Local\Programs\Python\Python39\lib\threading.py", line 1266, in run
    self.function(*self.args, **self.kwargs)
  File "C:\pybot\pybot2.py", line 141, in speak_15h55
    engine.runAndWait()
  File "C:\Users\Formateur\AppData\Local\Programs\Python\Python39\lib\site-packages\pyttsx3\engine.py", line 177, in runAndWait
    raise RuntimeError('run loop already started')
RuntimeError: run loop already started
Exception in thread Thread-8:
Traceback (most recent call last):
  File "C:\Users\Formateur\AppData\Local\Programs\Python\Python39\lib\threading.py", line 954, in _bootstrap_inner
    self.run()
  File "C:\Users\Formateur\AppData\Local\Programs\Python\Python39\lib\threading.py", line 1266, in run
    self.function(*self.args, **self.kwargs)
  File "C:\pybot\pybot2.py", line 156, in speak_16h
    engine.runAndWait()
  File "C:\Users\Formateur\AppData\Local\Programs\Python\Python39\lib\site-packages\pyttsx3\engine.py", line 177, in runAndWait
    raise RuntimeError('run loop already started')
RuntimeError: run loop already started
Exception in thread Thread-9:
Traceback (most recent call last):
  File "C:\Users\Formateur\AppData\Local\Programs\Python\Python39\lib\threading.py", line 954, in _bootstrap_inner
    self.run()
  File "C:\Users\Formateur\AppData\Local\Programs\Python\Python39\lib\threading.py", line 1266, in run
    self.function(*self.args, **self.kwargs)
  File "C:\pybot\pybot2.py", line 171, in speak_16h55
    engine.runAndWait()
  File "C:\Users\Formateur\AppData\Local\Programs\Python\Python39\lib\site-packages\pyttsx3\engine.py", line 177, in runAndWait
    raise RuntimeError('run loop already started')
RuntimeError: run loop already started
